Workbook

Sheet Brawler
B3: =References!$F$2 -> Name | D3: Wait | G3: =References!$F$2 -> Name | I3: Strike | L3: =References!$F$2 -> Name | N3: Heavy Strike
B4: =References!$F$3 -> Class | D4: =References!$E$2 -> Creature | G4: =References!$F$3 -> Class | I4: =References!$E$2 -> Creature | L4: =References!$F$3 -> Class | N4: =References!$E$2 -> Creature
B5: =References!$F$4 -> Type | G5: =References!$F$4 -> Type | I5: =References!$B$2 -> Offensive | L5: =References!$F$4 -> Type | N5: =References!$B$2 -> Offensive
B6: =References!$F$5 -> Nb. Targets | G6: =References!$F$5 -> Nb. Targets | I6: 1 | L6: =References!$F$5 -> Nb. Targets | N6: 1
B7: =References!$F$6 -> Energy cost | D7: 0 | G7: =References!$F$6 -> Energy cost | I7: 1 | L7: =References!$F$6 -> Energy cost | N7: 2
B8: Initiative | D8: 1 | G8: Initiative | I8: 1 | L8: Initiative | N8: 1
B9: Critical Chance | D9: 0 | G9: Critical Chance | I9: 0 | L9: Critical Chance | N9: 0
B10: =References!$G$2 -> Type | C10: =References!$G$3 -> Stat | D10: =References!$G$7 -> Nb | E10: =References!$G$8 -> Turns | G10: =References!$G$2 -> Type | H10: =References!$G$3 -> Stat | I10: =References!$G$7 -> Nb | J10: =References!$G$8 -> Turns | L10: =References!$G$2 -> Type | M10: =References!$G$3 -> Stat | N10: =References!$G$7 -> Nb | O10: =References!$G$8 -> Turns
G11: =References!$C$2 -> Direct | H11: =References!$A$2 -> dmg | I11: 2 | L11: =References!$C$2 -> Direct | M11: =References!$A$2 -> dmg | N11: 3
B17: =References!$F$2 -> Name | D17: Pummel | G17: =References!$F$2 -> Name | I17: Guard
B18: =References!$F$3 -> Class | D18: =References!$D$2 -> Brawler | G18: =References!$F$3 -> Class | I18: =References!$D$2 -> Brawler
B19: =References!$F$4 -> Type | D19: =References!$B$2 -> Offensive | G19: =References!$F$4 -> Type | I19: =References!$B$3 -> Defensive
B20: =References!$F$5 -> Nb. Targets | D20: 1 | G20: =References!$F$5 -> Nb. Targets | I20: 1
B21: =References!$F$6 -> Energy cost | D21: 1 | G21: =References!$F$6 -> Energy cost | I21: 1
B22: Initiative | D22: 1 | G22: Initiative | I22: 1
B23: Critical Chance | D23: 0.667 | G23: Critical Chance | I23: 0
B24: =References!$G$2 -> Type | C24: =References!$G$3 -> Stat | D24: =References!$G$7 -> Nb | E24: =References!$G$8 -> Turns | G24: =References!$G$2 -> Type | H24: =References!$G$3 -> Stat | I24: =References!$G$7 -> Nb | J24: =References!$G$8 -> Turns
B25: =References!$C$2 -> Direct | C25: =References!$A$2 -> dmg | D25: 2 | G25: =References!$C$2 -> Direct | H25: =References!$A$5 -> def | I25: 1
G26: =References!$C$3 -> Temp | H26: =References!$A$5 -> def | I26: 1 | J26: 2
C30: =References!$F$2 -> Name | E30: Protective Slam | M30: =References!$F$2 -> Name | O30: Full Plate | W30: =References!$F$2 -> Name | Y30: Enraged Charge
C31: =References!$F$3 -> Class | E31: =References!$E$3 -> Mercenary | M31: =References!$F$3 -> Class | O31: =References!$E$4 -> Warlord | W31: =References!$F$3 -> Class | Y31: =References!$E$5 -> Berserker
C32: =References!$F$4 -> Type | E32: =References!$B$2 -> Offensive | M32: =References!$F$4 -> Type | O32: =References!$B$4 -> Passive | W32: =References!$F$4 -> Type | Y32: =References!$B$2 -> Offensive
C33: =References!$F$5 -> Nb. Targets | E33: 1 | M33: =References!$F$5 -> Nb. Targets | W33: =References!$F$5 -> Nb. Targets | Y33: 1
C34: =References!$F$6 -> Energy cost | E34: 2 | M34: =References!$F$6 -> Energy cost | W34: =References!$F$6 -> Energy cost | Y34: 3
C35: Initiative | E35: 1 | M35: Initiative | O35: 1 | W35: Initiative | Y35: 1
C36: Critical Chance | E36: 0.33 | M36: Critical Chance | O36: 0 | W36: Critical Chance | Y36: 0
C37: =References!$G$2 -> Type | D37: =References!$G$3 -> Stat | E37: =References!$G$7 -> Nb | F37: =References!$G$8 -> Turns | M37: =References!$G$2 -> Type | N37: =References!$G$3 -> Stat | O37: =References!$G$7 -> Nb | P37: =References!$G$8 -> Turns | W37: =References!$G$2 -> Type | X37: =References!$G$3 -> Stat | Y37: =References!$G$7 -> Nb | Z37: =References!$G$8 -> Turns
C38: =References!$C$2 -> Direct | D38: =References!$A$2 -> dmg | E38: 3 | M38: =References!$B$4 -> Passive | N38: =References!$A$5 -> def | O38: 1 | W38: =References!$C$2 -> Direct | X38: =References!$A$2 -> dmg | Y38: 4
C39: =References!$C$4 -> SelfDirect | D39: =References!$A$5 -> def | E39: 1 | W39: =References!$C$2 -> Direct | X39: =References!$A$2 -> dmg | Y39: 3
C40: =References!$C$5 -> SelfTemp | D40: =References!$A$5 -> def | E40: 1 | F40: 2
A45: =References!$F$2 -> Name | C45: Chain Slash | F45: =References!$F$2 -> Name | H45: Thundering Seal | K45: =References!$F$2 -> Name | M45: Crushing Stomp | P45: =References!$F$2 -> Name | R45: Restorative Gush | U45: =References!$F$2 -> Name | W45: Tornado | Z45: =References!$F$2 -> Name | AB45: Psycho Rush
A46: =References!$F$3 -> Class | C46: =References!$E$3 -> Mercenary | F46: =References!$F$3 -> Class | H46: =References!$E$3 -> Mercenary | K46: =References!$F$3 -> Class | M46: =References!$E$4 -> Warlord | P46: =References!$F$3 -> Class | R46: =References!$E$4 -> Warlord | U46: =References!$F$3 -> Class | W46: =References!$E$5 -> Berserker | Z46: =References!$F$3 -> Class | AB46: =References!$E$5 -> Berserker
A47: =References!$F$4 -> Type | C47: =References!$B$2 -> Offensive | F47: =References!$F$4 -> Type | H47: =References!$B$3 -> Defensive | K47: =References!$F$4 -> Type | M47: =References!$B$2 -> Offensive | P47: =References!$F$4 -> Type | R47: =References!$B$3 -> Defensive | U47: =References!$F$4 -> Type | W47: =References!$B$3 -> Defensive | Z47: =References!$F$4 -> Type | AB47: =References!$B$2 -> Offensive
A48: =References!$F$5 -> Nb. Targets | C48: 2 | F48: =References!$F$5 -> Nb. Targets | H48: 1 | K48: =References!$F$5 -> Nb. Targets | M48: 1 | P48: =References!$F$5 -> Nb. Targets | R48: 1 | U48: =References!$F$5 -> Nb. Targets | W48: 3 | Z48: =References!$F$5 -> Nb. Targets | AB48: 1
A49: =References!$F$6 -> Energy cost | C49: 3 | F49: =References!$F$6 -> Energy cost | H49: 2 | K49: =References!$F$6 -> Energy cost | M49: 4 | P49: =References!$F$6 -> Energy cost | R49: 2 | U49: =References!$F$6 -> Energy cost | W49: 2 | Z49: =References!$F$6 -> Energy cost | AB49: 3
A50: Initiative | C50: 2 | F50: Initiative | H50: 2 | K50: Initiative | M50: 1 | P50: Initiative | R50: 2 | U50: Initiative | W50: 1 | Z50: Initiative | AB50: 1
A51: Critical Chance | C51: 0.5 | F51: Critical Chance | H51: 0 | K51: Critical Chance | M51: 0.667 | P51: Critical Chance | R51: 0.17 | U51: Critical Chance | W51: 0.33 | Z51: Critical Chance | AB51: 0.33
A52: =References!$G$2 -> Type | B52: =References!$G$3 -> Stat | C52: =References!$G$7 -> Nb | D52: =References!$G$8 -> Turns | F52: =References!$G$2 -> Type | G52: =References!$G$3 -> Stat | H52: =References!$G$7 -> Nb | I52: =References!$G$8 -> Turns | K52: =References!$G$2 -> Type | L52: =References!$G$3 -> Stat | M52: =References!$G$7 -> Nb | N52: =References!$G$8 -> Turns | P52: =References!$G$2 -> Type | Q52: =References!$G$3 -> Stat | R52: =References!$G$7 -> Nb | S52: =References!$G$8 -> Turns | U52: =References!$G$2 -> Type | V52: =References!$G$3 -> Stat | W52: =References!$G$7 -> Nb | X52: =References!$G$8 -> Turns | Z52: =References!$G$2 -> Type | AA52: =References!$G$3 -> Stat | AB52: =References!$G$7 -> Nb | AC52: =References!$G$8 -> Turns
A53: =References!$C$2 -> Direct | B53: =References!$A$2 -> dmg | C53: 5 | F53: =References!$C$2 -> Direct | G53: =References!$A$5 -> def | H53: 2 | K53: =References!$C$2 -> Direct | L53: =References!$A$2 -> dmg | M53: 6 | P53: =References!$C$2 -> Direct | Q53: =References!$A$3 -> hp | R53: 6 | U53: =References!$C$2 -> Direct | V53: =References!$A$2 -> dmg | W53: 4 | Z53: =References!$C$2 -> Direct | AA53: =References!$A$2 -> dmg | AB53: 9
F54: =References!$C$2 -> Direct | G54: =References!$A$7 -> rtl | H54: 2 | K54: =References!$C$2 -> Direct | L54: =References!$A$8 -> stun | M54: 1 | Z54: =References!$C$5 -> SelfTemp | AA54: =References!$A$5 -> def | AB54: -2 | AC54: 1
...

Sheet Scoundrel
B3: =References!$F$2 -> Name | D3: Wait | G3: =References!$F$2 -> Name | I3: Strike | L3: =References!$F$2 -> Name | N3: Heavy Strike
B4: =References!$F$3 -> Class | D4: =References!$E$2 -> Creature | G4: =References!$F$3 -> Class | I4: =References!$E$2 -> Creature | L4: =References!$F$3 -> Class | N4: =References!$E$2 -> Creature
B5: =References!$F$4 -> Type | G5: =References!$F$4 -> Type | I5: =References!$B$2 -> Offensive | L5: =References!$F$4 -> Type | N5: =References!$B$2 -> Offensive
B6: =References!$F$5 -> Nb. Targets | G6: =References!$F$5 -> Nb. Targets | I6: 1 | L6: =References!$F$5 -> Nb. Targets | N6: 1
B7: =References!$F$6 -> Energy cost | D7: 0 | G7: =References!$F$6 -> Energy cost | I7: 1 | L7: =References!$F$6 -> Energy cost | N7: 2
B8: Initiative | D8: 1 | G8: Initiative | I8: 1 | L8: Initiative | N8: 1
B9: Critical Chance | D9: 0 | G9: Critical Chance | I9: 0 | L9: Critical Chance | N9: 0
B10: =References!$G$2 -> Type | C10: =References!$G$3 -> Stat | D10: =References!$G$7 -> Nb | E10: =References!$G$8 -> Turns | G10: =References!$G$2 -> Type | H10: =References!$G$3 -> Stat | I10: =References!$G$7 -> Nb | J10: =References!$G$8 -> Turns | L10: =References!$G$2 -> Type | M10: =References!$G$3 -> Stat | N10: =References!$G$7 -> Nb | O10: =References!$G$8 -> Turns
G11: =References!$C$2 -> Direct | H11: =References!$A$2 -> dmg | I11: 2 | L11: =References!$C$2 -> Direct | M11: =References!$A$2 -> dmg | N11: 3
B17: =References!$F$2 -> Name | D17: Poison Slash | G17: =References!$F$2 -> Name | I17: Throwing Star
B18: =References!$F$3 -> Class | D18: =References!$D$3 -> Scoundrel | G18: =References!$F$3 -> Class | I18: =References!$D$3 -> Scoundrel
B19: =References!$F$4 -> Type | D19: =References!$B$2 -> Offensive | G19: =References!$F$4 -> Type | I19: =References!$B$2 -> Offensive
B20: =References!$F$5 -> Nb. Targets | D20: 1 | G20: =References!$F$5 -> Nb. Targets | I20: 1
B21: =References!$F$6 -> Energy cost | D21: 2 | G21: =References!$F$6 -> Energy cost | I21: 1
B22: Initiative | D22: 1 | G22: Initiative | I22: 2
B23: Critical Chance | D23: 0 | G23: Critical Chance | I23: 0
B24: =References!$G$2 -> Type | C24: =References!$G$3 -> Stat | D24: =References!$G$7 -> Nb | E24: =References!$G$8 -> Turns | G24: =References!$G$2 -> Type | H24: =References!$G$3 -> Stat | I24: =References!$G$7 -> Nb | J24: =References!$G$8 -> Turns
B25: =References!$C$2 -> Direct | C25: =References!$A$2 -> dmg | D25: 2 | G25: =References!$C$2 -> Direct | H25: =References!$A$2 -> dmg | I25: 2
B26: =References!$C$3 -> Temp | C26: =References!$A$2 -> dmg | D26: 1 | E26: 2
H28: l
C30: =References!$F$2 -> Name | E30: Parasite Jab | M30: =References!$F$2 -> Name | O30: Momentum | W30: =References!$F$2 -> Name | Y30: Noxious Cure
C31: =References!$F$3 -> Class | E31: =References!$E$10 -> Leech | M31: =References!$F$3 -> Class | O31: =References!$E$7 -> Assassin | W31: =References!$F$3 -> Class | Y31: =References!$E$6 -> Trickster
C32: =References!$F$4 -> Type | E32: =References!$B$2 -> Offensive | M32: =References!$F$4 -> Type | O32: =References!$B$4 -> Passive | W32: =References!$F$4 -> Type | Y32: =References!$B$3 -> Defensive
C33: =References!$F$5 -> Nb. Targets | E33: 1 | M33: =References!$F$5 -> Nb. Targets | W33: =References!$F$5 -> Nb. Targets | Y33: 3
C34: =References!$F$6 -> Energy cost | E34: 2 | M34: =References!$F$6 -> Energy cost | W34: =References!$F$6 -> Energy cost | Y34: 2
C35: Initiative | E35: 1 | M35: Initiative | O35: 3 | W35: Initiative | Y35: 1
C36: Critical Chance | E36: 0.5 | M36: Critical Chance | O36: 0 | W36: Critical Chance | Y36: 0.333
C37: =References!$G$2 -> Type | D37: =References!$G$3 -> Stat | E37: =References!$G$7 -> Nb | F37: =References!$G$8 -> Turns | M37: =References!$G$2 -> Type | N37: =References!$G$3 -> Stat | O37: =References!$G$7 -> Nb | P37: =References!$G$8 -> Turns | W37: =References!$G$2 -> Type | X37: =References!$G$3 -> Stat | Y37: =References!$G$7 -> Nb | Z37: =References!$G$8 -> Turns
C38: =References!$C$2 -> Direct | D38: =References!$A$2 -> dmg | E38: 2 | W38: =References!$C$2 -> Direct | X38: =References!$A$3 -> hp | Y38: 3
C39: =References!$C$4 -> SelfDirect | D39: =References!$A$3 -> hp | E39: 2 | W39: =References!$C$2 -> Direct | X39: def | Y39: -2
A45: =References!$F$2 -> Name | C45: Hateful Sacrifice | F45: =References!$F$2 -> Name | H45: Soul Devourer | K45: =References!$F$2 -> Name | M45: Death Squad | P45: =References!$F$2 -> Name | R45: Mortal Wound | U45: =References!$F$2 -> Name | W45: Tranquilizer Dart | Z45: =References!$F$2 -> Name | AB45: Infectious Blast
A46: =References!$F$3 -> Class | C46: =References!$E$10 -> Leech | F46: =References!$F$3 -> Class | H46: =References!$E$10 -> Leech | K46: =References!$F$3 -> Class | M46: =References!$E$7 -> Assassin | P46: =References!$F$3 -> Class | R46: =References!$E$7 -> Assassin | U46: =References!$F$3 -> Class | W46: =References!$E$6 -> Trickster | Z46: =References!$F$3 -> Class | AB46: =References!$E$6 -> Trickster
A47: =References!$F$4 -> Type | C47: =References!$B$2 -> Offensive | F47: =References!$F$4 -> Type | H47: =References!$B$3 -> Defensive | K47: =References!$F$4 -> Type | M47: =References!$B$3 -> Defensive | P47: =References!$F$4 -> Type | R47: =References!$B$3 -> Defensive | U47: =References!$F$4 -> Type | W47: =References!$B$2 -> Offensive | Z47: =References!$F$4 -> Type | AB47: =References!$B$2 -> Offensive
A48: =References!$F$5 -> Nb. Targets | C48: 1 | F48: =References!$F$5 -> Nb. Targets | H48: 1 | K48: =References!$F$5 -> Nb. Targets | M48: 3 | P48: =References!$F$5 -> Nb. Targets | R48: 1 | U48: =References!$F$5 -> Nb. Targets | W48: 1 | Z48: =References!$F$5 -> Nb. Targets | AB48: 3
A49: =References!$F$6 -> Energy cost | C49: 3 | F49: =References!$F$6 -> Energy cost | H49: 3 | K49: =References!$F$6 -> Energy cost | M49: 2 | P49: =References!$F$6 -> Energy cost | R49: 3 | U49: =References!$F$6 -> Energy cost | W49: 3 | Z49: =References!$F$6 -> Energy cost | AB49: 1
A50: Initiative | C50: 3 | F50: Initiative | H50: 2 | K50: Initiative | M50: 3 | P50: Initiative | R50: 2 | U50: Initiative | W50: 2 | Z50: Initiative | AB50: 2
A51: Critical Chance | C51: 0.5 | F51: Critical Chance | H51: 0 | K51: Critical Chance | M51: 0 | P51: Critical Chance | R51: 0.5 | U51: Critical Chance | W51: 0 | Z51: Critical Chance | AB51: 0
A52: =References!$G$2 -> Type | B52: =References!$G$3 -> Stat | C52: =References!$G$7 -> Nb | D52: =References!$G$8 -> Turns | F52: =References!$G$2 -> Type | G52: =References!$G$3 -> Stat | H52: =References!$G$7 -> Nb | I52: =References!$G$8 -> Turns | K52: =References!$G$2 -> Type | L52: =References!$G$3 -> Stat | M52: =References!$G$7 -> Nb | N52: =References!$G$8 -> Turns | P52: =References!$G$2 -> Type | Q52: =References!$G$3 -> Stat | R52: =References!$G$7 -> Nb | S52: =References!$G$8 -> Turns | U52: =References!$G$2 -> Type | V52: =References!$G$3 -> Stat | W52: =References!$G$7 -> Nb | X52: =References!$G$8 -> Turns | Z52: =References!$G$2 -> Type | AA52: =References!$G$3 -> Stat | AB52: =References!$G$7 -> Nb | AC52: =References!$G$8 -> Turns
A53: =References!$C$2 -> Direct | B53: =References!$A$2 -> dmg | C53: 10 | F53: =References!$C$2 -> Direct | G53: =References!$A$2 -> dmg | H53: 3 | K53: Temp | L53: init | M53: same | N53: 1 | P53: =References!$C$2 -> Direct | Q53: =References!$A$2 -> dmg | R53: 4 | U53: =References!$C$2 -> Direct | V53: =References!$A$2 -> dmg | W53: 3 | Z53: =References!$C$2 -> Direct | AA53: =References!$A$5 -> def | AB53: 2
A54: =References!$C$4 -> SelfDirect | B54: =References!$A$3 -> hp | C54: -4 | F54: =References!$C$2 -> Direct | G54: =References!$A$4 -> enrg | H54: 2 | K54: Temp | L54: crit | M54: 1 | N54: 1 | P54: Temp | Q54: dmg | R54: 4 | S54: 2 | U54: =References!$C$2 -> Direct | V54: =References!$A$8 -> stun | W54: 1

Sheet Sorcerer
B3: =References!$F$2 -> Name | D3: Wait | G3: =References!$F$2 -> Name | I3: Strike | L3: =References!$F$2 -> Name | N3: Heavy Strike
B4: =References!$F$3 -> Class | D4: =References!$E$2 -> Creature | G4: =References!$F$3 -> Class | I4: =References!$E$2 -> Creature | L4: =References!$F$3 -> Class | N4: =References!$E$2 -> Creature
B5: =References!$F$4 -> Type | G5: =References!$F$4 -> Type | I5: =References!$B$2 -> Offensive | L5: =References!$F$4 -> Type | N5: =References!$B$2 -> Offensive
B6: =References!$F$5 -> Nb. Targets | G6: =References!$F$5 -> Nb. Targets | I6: 1 | L6: =References!$F$5 -> Nb. Targets | N6: 1
B7: =References!$F$6 -> Energy cost | D7: 0 | G7: =References!$F$6 -> Energy cost | I7: 1 | L7: =References!$F$6 -> Energy cost | N7: 2
B8: Initiative | D8: 1 | G8: Initiative | I8: 1 | L8: Initiative | N8: 1
B9: Critical Chance | D9: 0 | G9: Critical Chance | I9: 0 | L9: Critical Chance | N9: 0
B10: =References!$G$2 -> Type | C10: =References!$G$3 -> Stat | D10: =References!$G$7 -> Nb | E10: =References!$G$8 -> Turns | G10: =References!$G$2 -> Type | H10: =References!$G$3 -> Stat | I10: =References!$G$7 -> Nb | J10: =References!$G$8 -> Turns | L10: =References!$G$2 -> Type | M10: =References!$G$3 -> Stat | N10: =References!$G$7 -> Nb | O10: =References!$G$8 -> Turns
G11: =References!$C$2 -> Direct | H11: =References!$A$2 -> dmg | I11: 2 | L11: =References!$C$2 -> Direct | M11: =References!$A$2 -> dmg | N11: 3
B17: =References!$F$2 -> Name | D17: Lightning Bolt | G17: =References!$F$2 -> Name | I17: Rejuvenate
B18: =References!$F$3 -> Class | D18: =References!$D$4 -> Sorcerer | G18: =References!$F$3 -> Class | I18: =References!$D$4 -> Sorcerer
B19: =References!$F$4 -> Type | D19: =References!$B$2 -> Offensive | G19: =References!$F$4 -> Type | I19: =References!$B$3 -> Defensive
B20: =References!$F$5 -> Nb. Targets | D20: 1 | G20: =References!$F$5 -> Nb. Targets | I20: 1
B21: =References!$F$6 -> Energy cost | D21: 2 | G21: =References!$F$6 -> Energy cost | I21: 1
B22: Initiative | D22: 1 | G22: Initiative | I22: 1
B23: Critical Chance | D23: 0.667 | G23: Critical Chance | I23: =0+1/6 -> 0.16666667
B24: =References!$G$2 -> Type | C24: =References!$G$3 -> Stat | D24: =References!$G$7 -> Nb | E24: =References!$G$8 -> Turns | G24: =References!$G$2 -> Type | H24: =References!$G$3 -> Stat | I24: =References!$G$7 -> Nb | J24: =References!$G$8 -> Turns
B25: =References!$C$2 -> Direct | C25: =References!$A$2 -> dmg | D25: 3 | G25: =References!$C$2 -> Direct | H25: =References!$A$3 -> hp | I25: 3
C30: =References!$F$2 -> Name | E30: Meteor | M30: =References!$F$2 -> Name | O30: Summon Minions | W30: =References!$F$2 -> Name | Y30: Healing Screech
C31: =References!$F$3 -> Class | E31: =References!$E$9 -> Wizard | M31: =References!$F$3 -> Class | O31: =References!$E$8 -> Necromancer | W31: =References!$F$3 -> Class | Y31: =References!$E$11 -> Shaman
C32: =References!$F$4 -> Type | E32: =References!$B$2 -> Offensive | M32: =References!$F$4 -> Type | O32: =References!$B$3 -> Defensive | W32: =References!$F$4 -> Type | Y32: =References!$B$3 -> Defensive
C33: =References!$F$5 -> Nb. Targets | E33: 3 | M33: =References!$F$5 -> Nb. Targets | W33: =References!$F$5 -> Nb. Targets | Y33: 1
C34: =References!$F$6 -> Energy cost | E34: 3 | M34: =References!$F$6 -> Energy cost | O34: 2 | W34: =References!$F$6 -> Energy cost | Y34: 2
C35: Initiative | E35: 1 | M35: Initiative | O35: 1 | W35: Initiative | Y35: 1
C36: Critical Chance | E36: 0.5 | M36: Critical Chance | O36: 0 | W36: Critical Chance | Y36: 0.5
C37: =References!$G$2 -> Type | D37: =References!$G$3 -> Stat | E37: =References!$G$7 -> Nb | F37: =References!$G$8 -> Turns | M37: =References!$G$2 -> Type | N37: =References!$G$3 -> Stat | O37: =References!$G$7 -> Nb | P37: =References!$G$8 -> Turns | W37: =References!$G$2 -> Type | X37: =References!$G$3 -> Stat | Y37: =References!$G$7 -> Nb | Z37: =References!$G$8 -> Turns
C38: =References!$C$2 -> Direct | D38: =References!$A$2 -> dmg | E38: 4 | W38: =References!$C$2 -> Direct | X38: =References!$A$3 -> hp | Y38: 2
W39: =References!$C$3 -> Temp | X39: =References!$A$3 -> hp | Y39: 2 | Z39: 1
A45: =References!$F$2 -> Name | C45: Ice Spear | F45: =References!$F$2 -> Name | H45: Engulfing Flames | K45: =References!$F$2 -> Name | M45: Revenant Guards | P45: =References!$F$2 -> Name | R45: Crazed Specters | U45: =References!$F$2 -> Name | W45: Toxic Waves | Z45: =References!$F$2 -> Name | AB45: Restoring Burst
A46: =References!$F$3 -> Class | C46: =References!$E$9 -> Wizard | F46: =References!$F$3 -> Class | H46: =References!$E$9 -> Wizard | K46: =References!$F$3 -> Class | M46: =References!$E$8 -> Necromancer | P46: =References!$F$3 -> Class | R46: =References!$E$8 -> Necromancer | U46: =References!$F$3 -> Class | W46: =References!$E$11 -> Shaman | Z46: =References!$F$3 -> Class | AB46: =References!$E$11 -> Shaman
A47: =References!$F$4 -> Type | C47: =References!$B$2 -> Offensive | F47: =References!$F$4 -> Type | H47: =References!$B$2 -> Offensive | K47: =References!$F$4 -> Type | M47: =References!$B$3 -> Defensive | P47: =References!$F$4 -> Type | R47: =References!$B$2 -> Offensive | U47: =References!$F$4 -> Type | W47: =References!$B$2 -> Offensive | Z47: =References!$F$4 -> Type | AB47: =References!$B$3 -> Defensive
A48: =References!$F$5 -> Nb. Targets | C48: 1 | F48: =References!$F$5 -> Nb. Targets | H48: 1 | K48: =References!$F$5 -> Nb. Targets | M48: 3 | P48: =References!$F$5 -> Nb. Targets | R48: 3 | U48: =References!$F$5 -> Nb. Targets | W48: 3 | Z48: =References!$F$5 -> Nb. Targets | AB48: 1
A49: =References!$F$6 -> Energy cost | C49: 2 | F49: =References!$F$6 -> Energy cost | H49: 3 | K49: =References!$F$6 -> Energy cost | M49: 2 | P49: =References!$F$6 -> Energy cost | R49: 3 | U49: =References!$F$6 -> Energy cost | W49: 3 | Z49: =References!$F$6 -> Energy cost | AB49: 2
A50: Initiative | C50: 2 | F50: Initiative | H50: 1 | K50: Initiative | M50: 1 | P50: Initiative | R50: 1 | U50: Initiative | W50: 2 | Z50: Initiative | AB50: 2
A51: Critical Chance | C51: 0.5 | F51: Critical Chance | H51: 0.33 | K51: Critical Chance | M51: 0.33 | P51: Critical Chance | R51: 0.33 | U51: Critical Chance | W51: 0.33 | Z51: Critical Chance | AB51: 0
A52: =References!$G$2 -> Type | B52: =References!$G$3 -> Stat | C52: =References!$G$7 -> Nb | D52: =References!$G$8 -> Turns | F52: =References!$G$2 -> Type | G52: =References!$G$3 -> Stat | H52: =References!$G$7 -> Nb | I52: =References!$G$8 -> Turns | K52: =References!$G$2 -> Type | L52: =References!$G$3 -> Stat | M52: =References!$G$7 -> Nb | N52: =References!$G$8 -> Turns | P52: =References!$G$2 -> Type | Q52: =References!$G$3 -> Stat | R52: =References!$G$7 -> Nb | S52: =References!$G$8 -> Turns | U52: =References!$G$2 -> Type | V52: =References!$G$3 -> Stat | W52: =References!$G$7 -> Nb | X52: =References!$G$8 -> Turns | Z52: =References!$G$2 -> Type | AA52: =References!$G$3 -> Stat | AB52: =References!$G$7 -> Nb | AC52: =References!$G$8 -> Turns
A53: =References!$C$2 -> Direct | B53: =References!$A$2 -> dmg | C53: 4 | F53: =References!$C$2 -> Direct | G53: =References!$A$2 -> dmg | H53: 9 | K53: =References!$C$2 -> Direct | L53: =References!$A$5 -> def | M53: 2 | P53: =References!$C$2 -> Direct | Q53: =References!$A$2 -> dmg | R53: 6 | U53: =References!$C$2 -> Direct | V53: =References!$A$2 -> dmg | W53: 3 | Z53: =References!$C$2 -> Direct | AA53: =References!$A$3 -> hp | AB53: 3
A54: =References!$C$3 -> Temp | B54: init | C54: -2 | D54: 1 | K54: =References!$C$3 -> Temp | L54: =References!$A$5 -> def | M54: 2 | N54: 1 | U54: Temp | V54: dmg | W54: 2 | X54: 1 | Z54: =References!$C$2 -> Direct | AA54: =References!$A$4 -> enrg | AB54: 2

Sheet Ranger2
B3: =References!$F$2 -> Name | D3: Wait | G3: =References!$F$2 -> Name | I3: Attack | L3: =References!$F$2 -> Name | N3: Super Attack
B4: =References!$F$3 -> Class | D4: =References!$E$2 -> Creature | G4: =References!$F$3 -> Class | I4: =References!$E$2 -> Creature | L4: =References!$F$3 -> Class | N4: =References!$E$2 -> Creature
B5: =References!$F$4 -> Type | G5: =References!$F$4 -> Type | I5: =References!$B$2 -> Offensive | L5: =References!$F$4 -> Type | N5: =References!$B$2 -> Offensive
B6: =References!$F$5 -> Nb. Targets | G6: =References!$F$5 -> Nb. Targets | I6: 1 | L6: =References!$F$5 -> Nb. Targets | N6: 1
B7: =References!$F$6 -> Energy cost | D7: 0 | G7: =References!$F$6 -> Energy cost | I7: 1 | L7: =References!$F$6 -> Energy cost | N7: 2
B8: Initiative | D8: 1 | G8: Initiative | I8: 1 | L8: Initiative | N8: 1
B9: Critical Chance | D9: 0 | G9: Critical Chance | I9: 0 | L9: Critical Chance | N9: 0
B10: =References!$G$2 -> Type | C10: =References!$G$3 -> Stat | D10: =References!$G$7 -> Nb | E10: =References!$G$8 -> Turns | G10: =References!$G$2 -> Type | H10: =References!$G$3 -> Stat | I10: =References!$G$7 -> Nb | J10: =References!$G$8 -> Turns | L10: =References!$G$2 -> Type | M10: =References!$G$3 -> Stat | N10: =References!$G$7 -> Nb | O10: =References!$G$8 -> Turns
G11: =References!$C$2 -> Direct | H11: =References!$A$2 -> dmg | I11: 2 | L11: =References!$C$2 -> Direct | M11: =References!$A$2 -> dmg | N11: 3
B17: =References!$F$2 -> Name | D17: Mini Poison | G17: =References!$F$2 -> Name | I17: Quick Stab
B18: =References!$F$3 -> Class | D18: =References!$D$3 -> Scoundrel | G18: =References!$F$3 -> Class | I18: =References!$D$3 -> Scoundrel
B19: =References!$F$4 -> Type | D19: =References!$B$2 -> Offensive | G19: =References!$F$4 -> Type | I19: =References!$B$2 -> Offensive
B20: =References!$F$5 -> Nb. Targets | D20: 1 | G20: =References!$F$5 -> Nb. Targets | I20: 1
B21: =References!$F$6 -> Energy cost | D21: 2 | G21: =References!$F$6 -> Energy cost | I21: 1
B22: Initiative | D22: 1 | G22: Initiative | I22: 3
B23: Critical Chance | D23: 0 | G23: Critical Chance | I23: 0
B24: =References!$G$2 -> Type | C24: =References!$G$3 -> Stat | D24: =References!$G$7 -> Nb | E24: =References!$G$8 -> Turns | G24: =References!$G$2 -> Type | H24: =References!$G$3 -> Stat | I24: =References!$G$7 -> Nb | J24: =References!$G$8 -> Turns
B25: =References!$C$2 -> Direct | C25: =References!$A$2 -> dmg | D25: 2 | G25: =References!$C$2 -> Direct | H25: =References!$A$2 -> dmg | I25: 2
B26: =References!$C$3 -> Temp | C26: =References!$A$2 -> dmg | D26: 1 | E26: 2
C30: =References!$F$2 -> Name | E30: Heal Over Time | M30: =References!$F$2 -> Name | O30: Speed | W30: =References!$F$2 -> Name | Y30: Call Beasts
C31: =References!$F$3 -> Class | E31: =References!#REF! -> #REF! | M31: =References!$F$3 -> Class | O31: =References!$E$7 -> Assassin | W31: =References!$F$3 -> Class | Y31: =References!$E$8 -> Necromancer
C32: =References!$F$4 -> Type | E32: =References!$B$3 -> Defensive | M32: =References!$F$4 -> Type | O32: =References!$B$4 -> Passive | W32: =References!$F$4 -> Type | Y32: =References!$B$3 -> Defensive
C33: =References!$F$5 -> Nb. Targets | E33: 1 | M33: =References!$F$5 -> Nb. Targets | W33: =References!$F$5 -> Nb. Targets
C34: =References!$F$6 -> Energy cost | E34: 2 | M34: =References!$F$6 -> Energy cost | W34: =References!$F$6 -> Energy cost | Y34: 2
C35: Initiative | E35: 1 | M35: Initiative | O35: 3 | W35: Initiative | Y35: 1
C36: Critical Chance | E36: 0.5 | M36: Critical Chance | O36: 0 | W36: Critical Chance | Y36: 0
C37: =References!$G$2 -> Type | D37: =References!$G$3 -> Stat | E37: =References!$G$7 -> Nb | F37: =References!$G$8 -> Turns | M37: =References!$G$2 -> Type | N37: =References!$G$3 -> Stat | O37: =References!$G$7 -> Nb | P37: =References!$G$8 -> Turns | W37: =References!$G$2 -> Type | X37: =References!$G$3 -> Stat | Y37: =References!$G$7 -> Nb | Z37: =References!$G$8 -> Turns
C38: =References!$C$2 -> Direct | D38: =References!$A$3 -> hp | E38: 2
C39: =References!$C$3 -> Temp | D39: =References!$A$3 -> hp | E39: 2 | F39: 1
A45: =References!$F$2 -> Name | C45: Retaliate | F45: =References!$F$2 -> Name | H45: Attack Balance | K45: =References!$F$2 -> Name | M45: Ninja Army | P45: =References!$F$2 -> Name | R45: Gros Poison | U45: =References!$F$2 -> Name | W45: Bear | Z45: =References!$F$2 -> Name | AB45: Eagle
A46: =References!$F$3 -> Class | C46: =References!#REF! -> #REF! | F46: =References!$F$3 -> Class | H46: =References!#REF! -> #REF! | K46: =References!$F$3 -> Class | M46: =References!$E$7 -> Assassin | P46: =References!$F$3 -> Class | R46: =References!$E$7 -> Assassin | U46: =References!$F$3 -> Class | W46: =References!$E$8 -> Necromancer | Z46: =References!$F$3 -> Class | AB46: =References!$E$8 -> Necromancer
A47: =References!$F$4 -> Type | C47: =References!$B$3 -> Defensive | F47: =References!$F$4 -> Type | H47: =References!$B$2 -> Offensive | K47: =References!$F$4 -> Type | M47: =References!$B$3 -> Defensive | P47: =References!$F$4 -> Type | R47: =References!$B$3 -> Defensive | U47: =References!$F$4 -> Type | W47: =References!$B$3 -> Defensive | Z47: =References!$F$4 -> Type | AB47: =References!$B$2 -> Offensive
A48: =References!$F$5 -> Nb. Targets | C48: 1 | F48: =References!$F$5 -> Nb. Targets | H48: 1 | K48: =References!$F$5 -> Nb. Targets | M48: 3 | P48: =References!$F$5 -> Nb. Targets | R48: 1 | U48: =References!$F$5 -> Nb. Targets | W48: 3 | Z48: =References!$F$5 -> Nb. Targets | AB48: 3
A49: =References!$F$6 -> Energy cost | C49: 2 | F49: =References!$F$6 -> Energy cost | H49: 3 | K49: =References!$F$6 -> Energy cost | M49: 2 | P49: =References!$F$6 -> Energy cost | R49: 3 | U49: =References!$F$6 -> Energy cost | W49: 2 | Z49: =References!$F$6 -> Energy cost | AB49: 3
A50: Initiative | C50: 1 | F50: Initiative | H50: 1 | K50: Initiative | M50: 3 | P50: Initiative | R50: 2 | U50: Initiative | W50: 1 | Z50: Initiative | AB50: 1
A51: Critical Chance | C51: 0 | F51: Critical Chance | H51: 0 | K51: Critical Chance | M51: 0 | P51: Critical Chance | R51: 0.5 | U51: Critical Chance | W51: 0.33 | Z51: Critical Chance | AB51: 0.33
A52: =References!$G$2 -> Type | B52: =References!$G$3 -> Stat | C52: =References!$G$7 -> Nb | D52: =References!$G$8 -> Turns | F52: =References!$G$2 -> Type | G52: =References!$G$3 -> Stat | H52: =References!$G$7 -> Nb | I52: =References!$G$8 -> Turns | K52: =References!$G$2 -> Type | L52: =References!$G$3 -> Stat | M52: =References!$G$7 -> Nb | N52: =References!$G$8 -> Turns | P52: =References!$G$2 -> Type | Q52: =References!$G$3 -> Stat | R52: =References!$G$7 -> Nb | S52: =References!$G$8 -> Turns | U52: =References!$G$2 -> Type | V52: =References!$G$3 -> Stat | W52: =References!$G$7 -> Nb | X52: =References!$G$8 -> Turns | Z52: =References!$G$2 -> Type | AA52: =References!$G$3 -> Stat | AB52: =References!$G$7 -> Nb | AC52: =References!$G$8 -> Turns
A53: =References!$C$2 -> Direct | B53: =References!$A$7 -> rtl | C53: 3 | F53: =References!$C$2 -> Direct | G53: =References!$A$2 -> dmg | H53: 8 | K53: Temp | L53: init | M53: same | N53: 1 | P53: =References!$C$2 -> Direct | Q53: =References!$A$2 -> dmg | R53: 3 | U53: =References!$C$2 -> Direct | V53: =References!$A$5 -> def | W53: 2 | Z53: =References!$C$2 -> Direct | AA53: =References!$A$2 -> dmg | AB53: 6
A54: =References!$C$3 -> Temp | B54: =References!$A$7 -> rtl | C54: 3 | D54: 1 | F54: =References!$C$2 -> Direct | G54: =References!$A$5 -> def | H54: 2 | K54: Temp | L54: crit | M54: 1 | N54: 1 | P54: Temp | Q54: dmg | R54: 3 | S54: 2 | U54: =References!$C$3 -> Temp | V54: =References!$A$5 -> def | W54: 2 | X54: 1
F55: =References!$C$5 -> SelfTemp | G55: =References!$A$5 -> def | H55: 2 | I55: 1
...

Sheet Mage2
B3: =References!$F$2 -> Name | D3: Wait | G3: =References!$F$2 -> Name | I3: Attack | L3: =References!$F$2 -> Name | N3: Super Attack
B4: =References!$F$3 -> Class | D4: =References!$E$2 -> Creature | G4: =References!$F$3 -> Class | I4: =References!$E$2 -> Creature | L4: =References!$F$3 -> Class | N4: =References!$E$2 -> Creature
B5: =References!$F$4 -> Type | G5: =References!$F$4 -> Type | I5: =References!$B$2 -> Offensive | L5: =References!$F$4 -> Type | N5: =References!$B$2 -> Offensive
B6: =References!$F$5 -> Nb. Targets | G6: =References!$F$5 -> Nb. Targets | I6: 1 | L6: =References!$F$5 -> Nb. Targets | N6: 1
B7: =References!$F$6 -> Energy cost | D7: 0 | G7: =References!$F$6 -> Energy cost | I7: 1 | L7: =References!$F$6 -> Energy cost | N7: 2
B8: Initiative | D8: 1 | G8: Initiative | I8: 1 | L8: Initiative | N8: 1
B9: Critical Chance | D9: 0 | G9: Critical Chance | I9: 0 | L9: Critical Chance | N9: 0
B10: =References!$G$2 -> Type | C10: =References!$G$3 -> Stat | D10: =References!$G$7 -> Nb | E10: =References!$G$8 -> Turns | G10: =References!$G$2 -> Type | H10: =References!$G$3 -> Stat | I10: =References!$G$7 -> Nb | J10: =References!$G$8 -> Turns | L10: =References!$G$2 -> Type | M10: =References!$G$3 -> Stat | N10: =References!$G$7 -> Nb | O10: =References!$G$8 -> Turns
G11: =References!$C$2 -> Direct | H11: =References!$A$2 -> dmg | I11: 2 | L11: =References!$C$2 -> Direct | M11: =References!$A$2 -> dmg | N11: 3
B17: =References!$F$2 -> Name | D17: Fireball | G17: =References!$F$2 -> Name | I17: Mini Heal
B18: =References!$F$3 -> Class | D18: =References!$D$4 -> Sorcerer | G18: =References!$F$3 -> Class | I18: =References!$D$4 -> Sorcerer
B19: =References!$F$4 -> Type | D19: =References!$B$2 -> Offensive | G19: =References!$F$4 -> Type | I19: =References!$B$3 -> Defensive
B20: =References!$F$5 -> Nb. Targets | D20: 1 | G20: =References!$F$5 -> Nb. Targets | I20: 1
B21: =References!$F$6 -> Energy cost | D21: 2 | G21: =References!$F$6 -> Energy cost | I21: 1
B22: Initiative | D22: 1 | G22: Initiative | I22: 1
B23: Critical Chance | D23: 0.667 | G23: Critical Chance | I23: =0+1/6 -> 0.16666667
B24: =References!$G$2 -> Type | C24: =References!$G$3 -> Stat | D24: =References!$G$7 -> Nb | E24: =References!$G$8 -> Turns | G24: =References!$G$2 -> Type | H24: =References!$G$3 -> Stat | I24: =References!$G$7 -> Nb | J24: =References!$G$8 -> Turns
B25: =References!$C$2 -> Direct | C25: =References!$A$2 -> dmg | D25: 3 | G25: =References!$C$2 -> Direct | H25: =References!$A$3 -> hp | I25: 3
C30: =References!$F$2 -> Name | E30: Explosion | M30: =References!$F$2 -> Name | O30: Leech | W30: =References!$F$2 -> Name | Y30: Enleve Def
C31: =References!$F$3 -> Class | E31: =References!$E$9 -> Wizard | M31: =References!$F$3 -> Class | O31: =References!$E$10 -> Leech | W31: =References!$F$3 -> Class | Y31: =References!$E$11 -> Shaman
C32: =References!$F$4 -> Type | E32: =References!$B$2 -> Offensive | M32: =References!$F$4 -> Type | O32: =References!$B$2 -> Offensive | W32: =References!$F$4 -> Type | Y32: =References!$B$2 -> Offensive
C33: =References!$F$5 -> Nb. Targets | E33: 3 | M33: =References!$F$5 -> Nb. Targets | O33: 1 | W33: =References!$F$5 -> Nb. Targets | Y33: 3
C34: =References!$F$6 -> Energy cost | E34: 3 | M34: =References!$F$6 -> Energy cost | O34: 2 | W34: =References!$F$6 -> Energy cost | Y34: 1
C35: Initiative | E35: 1 | M35: Initiative | O35: 1 | W35: Initiative | Y35: 2
C36: Critical Chance | E36: 0.5 | M36: Critical Chance | O36: 0.5 | W36: Critical Chance | Y36: 0
C37: =References!$G$2 -> Type | D37: =References!$G$3 -> Stat | E37: =References!$G$7 -> Nb | F37: =References!$G$8 -> Turns | M37: =References!$G$2 -> Type | N37: =References!$G$3 -> Stat | O37: =References!$G$7 -> Nb | P37: =References!$G$8 -> Turns | W37: =References!$G$2 -> Type | X37: =References!$G$3 -> Stat | Y37: =References!$G$7 -> Nb | Z37: =References!$G$8 -> Turns
C38: =References!$C$2 -> Direct | D38: =References!$A$2 -> dmg | E38: 4 | M38: =References!$C$2 -> Direct | N38: =References!$A$2 -> dmg | O38: 2 | W38: =References!$C$2 -> Direct | X38: =References!$A$5 -> def | Y38: 2
M39: =References!$C$4 -> SelfDirect | N39: =References!$A$3 -> hp | O39: 2
A45: =References!$F$2 -> Name | C45: Freeze | F45: =References!$F$2 -> Name | H45: Grosse Fireball | K45: =References!$F$2 -> Name | M45: Kamikaze | P45: =References!$F$2 -> Name | R45: Enleve energy | U45: =References!$F$2 -> Name | W45: Stun | Z45: =References!$F$2 -> Name | AB45: Energy Buff
A46: =References!$F$3 -> Class | C46: =References!$E$9 -> Wizard | F46: =References!$F$3 -> Class | H46: =References!$E$9 -> Wizard | K46: =References!$F$3 -> Class | M46: =References!$E$10 -> Leech | P46: =References!$F$3 -> Class | R46: =References!$E$10 -> Leech | U46: =References!$F$3 -> Class | W46: =References!$E$11 -> Shaman | Z46: =References!$F$3 -> Class | AB46: =References!$E$11 -> Shaman
A47: =References!$F$4 -> Type | C47: =References!$B$2 -> Offensive | F47: =References!$F$4 -> Type | H47: =References!$B$2 -> Offensive | K47: =References!$F$4 -> Type | M47: =References!$B$2 -> Offensive | P47: =References!$F$4 -> Type | R47: =References!$B$3 -> Defensive | U47: =References!$F$4 -> Type | W47: =References!$B$2 -> Offensive | Z47: =References!$F$4 -> Type | AB47: =References!$B$3 -> Defensive
A48: =References!$F$5 -> Nb. Targets | C48: 1 | F48: =References!$F$5 -> Nb. Targets | H48: 1 | K48: =References!$F$5 -> Nb. Targets | M48: 1 | P48: =References!$F$5 -> Nb. Targets | R48: 1 | U48: =References!$F$5 -> Nb. Targets | W48: 1 | Z48: =References!$F$5 -> Nb. Targets | AB48: 1
A49: =References!$F$6 -> Energy cost | C49: 2 | F49: =References!$F$6 -> Energy cost | H49: 3 | K49: =References!$F$6 -> Energy cost | M49: 3 | P49: =References!$F$6 -> Energy cost | R49: 3 | U49: =References!$F$6 -> Energy cost | W49: 3 | Z49: =References!$F$6 -> Energy cost | AB49: 2
A50: Initiative | C50: 2 | F50: Initiative | H50: 1 | K50: Initiative | M50: 3 | P50: Initiative | R50: 2 | U50: Initiative | W50: 2 | Z50: Initiative | AB50: 2
A51: Critical Chance | C51: 0.5 | F51: Critical Chance | H51: 0.33 | K51: Critical Chance | M51: 0.5 | P51: Critical Chance | R51: 0 | U51: Critical Chance | W51: 0 | Z51: Critical Chance | AB51: 0
A52: =References!$G$2 -> Type | B52: =References!$G$3 -> Stat | C52: =References!$G$7 -> Nb | D52: =References!$G$8 -> Turns | F52: =References!$G$2 -> Type | G52: =References!$G$3 -> Stat | H52: =References!$G$7 -> Nb | I52: =References!$G$8 -> Turns | K52: =References!$G$2 -> Type | L52: =References!$G$3 -> Stat | M52: =References!$G$7 -> Nb | N52: =References!$G$8 -> Turns | P52: =References!$G$2 -> Type | Q52: =References!$G$3 -> Stat | R52: =References!$G$7 -> Nb | S52: =References!$G$8 -> Turns | U52: =References!$G$2 -> Type | V52: =References!$G$3 -> Stat | W52: =References!$G$7 -> Nb | X52: =References!$G$8 -> Turns | Z52: =References!$G$2 -> Type | AA52: =References!$G$3 -> Stat | AB52: =References!$G$7 -> Nb | AC52: =References!$G$8 -> Turns
A53: =References!$C$2 -> Direct | B53: =References!$A$2 -> dmg | C53: 4 | F53: =References!$C$2 -> Direct | G53: =References!$A$2 -> dmg | H53: 9 | K53: =References!$C$2 -> Direct | L53: =References!$A$2 -> dmg | M53: 10 | P53: =References!$C$2 -> Direct | Q53: =References!$A$2 -> dmg | R53: 3 | U53: =References!$C$2 -> Direct | V53: =References!$A$2 -> dmg | W53: 3 | Z53: =References!$C$2 -> Direct | AA53: =References!$A$3 -> hp | AB53: 3
A54: =References!$C$3 -> Temp | B54: init | C54: -2 | D54: 1 | K54: =References!$C$4 -> SelfDirect | L54: =References!$A$3 -> hp | M54: -4 | P54: =References!$C$2 -> Direct | Q54: =References!$A$4 -> enrg | R54: 2 | U54: =References!$C$2 -> Direct | V54: =References!$A$8 -> stun | W54: 1 | Z54: =References!$C$2 -> Direct | AA54: =References!$A$4 -> enrg | AB54: 2

Sheet Fighter2
B3: =References!$F$2 -> Name | D3: Wait | G3: =References!$F$2 -> Name | I3: Attack | L3: =References!$F$2 -> Name | N3: Super Attack
B4: =References!$F$3 -> Class | D4: =References!$E$2 -> Creature | G4: =References!$F$3 -> Class | I4: =References!$E$2 -> Creature | L4: =References!$F$3 -> Class | N4: =References!$E$2 -> Creature
B5: =References!$F$4 -> Type | G5: =References!$F$4 -> Type | I5: =References!$B$2 -> Offensive | L5: =References!$F$4 -> Type | N5: =References!$B$2 -> Offensive
B6: =References!$F$5 -> Nb. Targets | G6: =References!$F$5 -> Nb. Targets | I6: 1 | L6: =References!$F$5 -> Nb. Targets | N6: 1
B7: =References!$F$6 -> Energy cost | D7: 0 | G7: =References!$F$6 -> Energy cost | I7: 1 | L7: =References!$F$6 -> Energy cost | N7: 2
B8: Initiative | D8: 1 | G8: Initiative | I8: 1 | L8: Initiative | N8: 1
B9: Critical Chance | D9: 0 | G9: Critical Chance | I9: 0 | L9: Critical Chance | N9: 0
B10: =References!$G$2 -> Type | C10: =References!$G$3 -> Stat | D10: =References!$G$7 -> Nb | E10: =References!$G$8 -> Turns | G10: =References!$G$2 -> Type | H10: =References!$G$3 -> Stat | I10: =References!$G$7 -> Nb | J10: =References!$G$8 -> Turns | L10: =References!$G$2 -> Type | M10: =References!$G$3 -> Stat | N10: =References!$G$7 -> Nb | O10: =References!$G$8 -> Turns
G11: =References!$C$2 -> Direct | H11: =References!$A$2 -> dmg | I11: 2 | L11: =References!$C$2 -> Direct | M11: =References!$A$2 -> dmg | N11: 3
B17: =References!$F$2 -> Name | D17: Attaque cool | G17: =References!$F$2 -> Name | I17: Shield
B18: =References!$F$3 -> Class | D18: =References!$D$2 -> Brawler | G18: =References!$F$3 -> Class | I18: =References!$D$2 -> Brawler
B19: =References!$F$4 -> Type | D19: =References!$B$2 -> Offensive | G19: =References!$F$4 -> Type | I19: =References!$B$3 -> Defensive
B20: =References!$F$5 -> Nb. Targets | D20: 1 | G20: =References!$F$5 -> Nb. Targets | I20: 1
B21: =References!$F$6 -> Energy cost | D21: 1 | G21: =References!$F$6 -> Energy cost | I21: 1
B22: Initiative | D22: 1 | G22: Initiative | I22: 1
B23: Critical Chance | D23: 0.667 | G23: Critical Chance | I23: 0
B24: =References!$G$2 -> Type | C24: =References!$G$3 -> Stat | D24: =References!$G$7 -> Nb | E24: =References!$G$8 -> Turns | G24: =References!$G$2 -> Type | H24: =References!$G$3 -> Stat | I24: =References!$G$7 -> Nb | J24: =References!$G$8 -> Turns
B25: =References!$C$2 -> Direct | C25: =References!$A$2 -> dmg | D25: 2 | G25: =References!$C$2 -> Direct | H25: =References!$A$5 -> def | I25: 1
G26: =References!$C$3 -> Temp | H26: =References!$A$5 -> def | I26: 1 | J26: 2
C30: =References!$F$2 -> Name | E30: Balance | M30: =References!$F$2 -> Name | O30: Full Plate | W30: =References!$F$2 -> Name | Y30: Double Hit
C31: =References!$F$3 -> Class | E31: =References!$E$3 -> Mercenary | M31: =References!$F$3 -> Class | O31: =References!$E$4 -> Warlord | W31: =References!$F$3 -> Class | Y31: =References!$E$5 -> Berserker
C32: =References!$F$4 -> Type | E32: =References!$B$2 -> Offensive | M32: =References!$F$4 -> Type | O32: =References!$B$4 -> Passive | W32: =References!$F$4 -> Type | Y32: =References!$B$2 -> Offensive
C33: =References!$F$5 -> Nb. Targets | E33: 1 | M33: =References!$F$5 -> Nb. Targets | W33: =References!$F$5 -> Nb. Targets | Y33: 1
C34: =References!$F$6 -> Energy cost | E34: 2 | M34: =References!$F$6 -> Energy cost | W34: =References!$F$6 -> Energy cost | Y34: 3
C35: Initiative | E35: 1 | M35: Initiative | O35: 1 | W35: Initiative | Y35: 1
C36: Critical Chance | E36: 0.33 | M36: Critical Chance | O36: 0 | W36: Critical Chance | Y36: 0
C37: =References!$G$2 -> Type | D37: =References!$G$3 -> Stat | E37: =References!$G$7 -> Nb | F37: =References!$G$8 -> Turns | M37: =References!$G$2 -> Type | N37: =References!$G$3 -> Stat | O37: =References!$G$7 -> Nb | P37: =References!$G$8 -> Turns | W37: =References!$G$2 -> Type | X37: =References!$G$3 -> Stat | Y37: =References!$G$7 -> Nb | Z37: =References!$G$8 -> Turns
C38: =References!$C$2 -> Direct | D38: =References!$A$2 -> dmg | E38: 3 | M38: =References!$B$4 -> Passive | N38: =References!$A$5 -> def | O38: 1 | W38: =References!$C$2 -> Direct | X38: =References!$A$2 -> dmg | Y38: 4
C39: =References!$C$4 -> SelfDirect | D39: =References!$A$5 -> def | E39: 1 | W39: =References!$C$2 -> Direct | X39: =References!$A$2 -> dmg | Y39: 3
C40: =References!$C$5 -> SelfTemp | D40: =References!$A$5 -> def | E40: 1 | F40: 2
A45: =References!$F$2 -> Name | C45: Cleave | F45: =References!$F$2 -> Name | H45: Shield / Retal | K45: =References!$F$2 -> Name | M45: Attack Stun | P45: =References!$F$2 -> Name | R45: Heal | U45: =References!$F$2 -> Name | W45: Tornado | Z45: =References!$F$2 -> Name | AB45: Maniac
A46: =References!$F$3 -> Class | C46: =References!$E$3 -> Mercenary | F46: =References!$F$3 -> Class | H46: =References!$E$3 -> Mercenary | K46: =References!$F$3 -> Class | M46: =References!$E$4 -> Warlord | P46: =References!$F$3 -> Class | R46: =References!$E$4 -> Warlord | U46: =References!$F$3 -> Class | W46: =References!$E$5 -> Berserker | Z46: =References!$F$3 -> Class | AB46: =References!$E$5 -> Berserker
A47: =References!$F$4 -> Type | C47: =References!$B$2 -> Offensive | F47: =References!$F$4 -> Type | H47: =References!$B$3 -> Defensive | K47: =References!$F$4 -> Type | M47: =References!$B$2 -> Offensive | P47: =References!$F$4 -> Type | R47: =References!$B$3 -> Defensive | U47: =References!$F$4 -> Type | W47: =References!$B$3 -> Defensive | Z47: =References!$F$4 -> Type | AB47: =References!$B$2 -> Offensive
A48: =References!$F$5 -> Nb. Targets | C48: 2 | F48: =References!$F$5 -> Nb. Targets | H48: 1 | K48: =References!$F$5 -> Nb. Targets | M48: 1 | P48: =References!$F$5 -> Nb. Targets | R48: 1 | U48: =References!$F$5 -> Nb. Targets | W48: 3 | Z48: =References!$F$5 -> Nb. Targets | AB48: 1
A49: =References!$F$6 -> Energy cost | C49: 3 | F49: =References!$F$6 -> Energy cost | H49: 2 | K49: =References!$F$6 -> Energy cost | M49: 4 | P49: =References!$F$6 -> Energy cost | R49: 2 | U49: =References!$F$6 -> Energy cost | W49: 2 | Z49: =References!$F$6 -> Energy cost | AB49: 3
A50: Initiative | C50: 2 | F50: Initiative | H50: 2 | K50: Initiative | M50: 1 | P50: Initiative | R50: 2 | U50: Initiative | W50: 1 | Z50: Initiative | AB50: 1
A51: Critical Chance | C51: 0.5 | F51: Critical Chance | H51: 0 | K51: Critical Chance | M51: 0.667 | P51: Critical Chance | R51: 0.17 | U51: Critical Chance | W51: 0.33 | Z51: Critical Chance | AB51: 0.33
A52: =References!$G$2 -> Type | B52: =References!$G$3 -> Stat | C52: =References!$G$7 -> Nb | D52: =References!$G$8 -> Turns | F52: =References!$G$2 -> Type | G52: =References!$G$3 -> Stat | H52: =References!$G$7 -> Nb | I52: =References!$G$8 -> Turns | K52: =References!$G$2 -> Type | L52: =References!$G$3 -> Stat | M52: =References!$G$7 -> Nb | N52: =References!$G$8 -> Turns | P52: =References!$G$2 -> Type | Q52: =References!$G$3 -> Stat | R52: =References!$G$7 -> Nb | S52: =References!$G$8 -> Turns | U52: =References!$G$2 -> Type | V52: =References!$G$3 -> Stat | W52: =References!$G$7 -> Nb | X52: =References!$G$8 -> Turns | Z52: =References!$G$2 -> Type | AA52: =References!$G$3 -> Stat | AB52: =References!$G$7 -> Nb | AC52: =References!$G$8 -> Turns
A53: =References!$C$2 -> Direct | B53: =References!$A$2 -> dmg | C53: 5 | F53: =References!$C$2 -> Direct | G53: =References!$A$5 -> def | H53: 2 | K53: =References!$C$2 -> Direct | L53: =References!$A$2 -> dmg | M53: 6 | P53: =References!$C$2 -> Direct | Q53: =References!$A$3 -> hp | R53: 6 | U53: =References!$C$2 -> Direct | V53: =References!$A$2 -> dmg | W53: 4 | Z53: =References!$C$2 -> Direct | AA53: =References!$A$2 -> dmg | AB53: 9
F54: =References!$C$2 -> Direct | G54: =References!$A$7 -> rtl | H54: 2 | K54: =References!$C$2 -> Direct | L54: =References!$A$8 -> stun | M54: 1 | Z54: =References!$C$5 -> SelfTemp | AA54: =References!$A$5 -> def | AB54: -2 | AC54: 1
...

Sheet Basic
A1: Basic
E3: =References!$F$2 -> Name | G3: Wait | R3: =References!$F$2 -> Name | T3: Attack | AE3: =References!$F$2 -> Name | AG3: Super Attack
E4: =References!$F$3 -> Class | G4: =References!$E$2 -> Creature | R4: =References!$F$3 -> Class | T4: =References!$E$2 -> Creature | AE4: =References!$F$3 -> Class | AG4: =References!$E$2 -> Creature
E5: =References!$F$4 -> Type | R5: =References!$F$4 -> Type | T5: =References!$B$2 -> Offensive | AE5: =References!$F$4 -> Type | AG5: =References!$B$2 -> Offensive
E6: =References!$F$5 -> Nb. Targets | R6: =References!$F$5 -> Nb. Targets | T6: 1 | AE6: =References!$F$5 -> Nb. Targets | AG6: 1
E7: =References!$F$6 -> Energy cost | G7: 0 | R7: =References!$F$6 -> Energy cost | T7: 1 | AE7: =References!$F$6 -> Energy cost | AG7: 2
A9: =References!$G$2 -> Type | B9: =References!$G$3 -> Stat | C9: =References!$G$4 -> Nb | D9: =References!$G$5 -> Turns | E9: =References!$G$6 -> % | F9: =References!$G$7 -> Nb | G9: =References!$G$8 -> Turns | H9: =References!$G$9 -> Nb | I9: =References!$G$10 -> Turns | J9: =References!$G$11 -> % | N9: =References!$G$2 -> Type | O9: =References!$G$3 -> Stat | P9: =References!$G$4 -> Nb | Q9: =References!$G$5 -> Turns | R9: =References!$G$6 -> % | S9: =References!$G$7 -> Nb | T9: =References!$G$8 -> Turns | U9: =References!$G$9 -> Nb | V9: =References!$G$10 -> Turns | W9: =References!$G$11 -> % | AA9: =References!$G$2 -> Type | AB9: =References!$G$3 -> Stat | AC9: =References!$G$4 -> Nb | AD9: =References!$G$5 -> Turns | AE9: =References!$G$6 -> % | AF9: =References!$G$7 -> Nb | AG9: =References!$G$8 -> Turns | AH9: =References!$G$9 -> Nb | AI9: =References!$G$10 -> Turns | AJ9: =References!$G$11 -> %
C10: =References!$H$2 -> High initiative | F10: =References!$H$3 -> Standard | H10: =References!$H$4 -> Low initiative | P10: =References!$H$2 -> High initiative | S10: =References!$H$3 -> Standard | U10: =References!$H$4 -> Low initiative | AC10: =References!$H$2 -> High initiative | AF10: =References!$H$3 -> Standard | AH10: =References!$H$4 -> Low initiative
N11: =References!$C$2 -> Direct | O11: =References!$A$2 -> dmg | P11: 1 | R11: 100 | S11: 1 | U11: 2 | W11: 100 | AA11: =References!$C$2 -> Direct | AB11: =References!$A$2 -> dmg | AC11: 2 | AE11: 100 | AF11: 3 | AH11: 3 | AJ11: 100

Sheet Sheet3
A1: =References!$F$2 -> Name | C1: Wait
A2: =References!$F$3 -> Class | C2: =References!$E$2 -> Creature
A3: =References!$F$4 -> Type
A4: =References!$F$5 -> Nb. Targets
A5: =References!$F$6 -> Energy cost | C5: 0
A6: Initiative | C6: 1
A7: Critical Chance | C7: 0
A8: =References!$G$2 -> Type | B8: =References!$G$3 -> Stat | C8: =References!$G$7 -> Nb | D8: =References!$G$8 -> Turns
A12: =References!$F$2 -> Name | C12: Attack
A13: =References!$F$3 -> Class | C13: =References!$E$2 -> Creature
A14: =References!$F$4 -> Type | C14: =References!$B$2 -> Offensive
A15: =References!$F$5 -> Nb. Targets | C15: 1
A16: =References!$F$6 -> Energy cost | C16: 1
A17: Initiative | C17: 1
A18: Critical Chance | C18: 0 | F18: Number times on 10 rounds | G18: =_xlfn.FLOOR.MATH(10/IF(OR(C16=1,C16=0),2,C16)) -> 5
A19: =References!$G$2 -> Type | B19: =References!$G$3 -> Stat | C19: =References!$G$7 -> Nb | D19: =References!$G$8 -> Turns | F19: Nb with crit chance | G19: NbCrit with turns | H19: Nb quick | I19: NbQuick with turns
A20: =References!$C$2 -> Direct | B20: =References!$A$2 -> dmg | C20: 2 | F20: =(C20+(1*C18))*C15 -> 2 | G20: =IF(D20="",F20,F20*D20) -> 2 | H20: =(C20-(1-C18)*1)*C15 -> 1 | I20: =IF(D20="",H20,H20*D20) -> 1
F21: Total dmg | G21: =SUM(G20) -> 2 | I21: =SUM(I20) -> 1
F23: Score Impact Direct | G23: Total point 10 round | H23: Score Impact sur 10 rounds | I23: Moy / Mana | J23: Score efficacité | K23: Final Score Standard
F24: =(G21/(20*C15))*100 -> 10 | G24: =G21*G18 -> 10 | H24: =(104.3421 + (9.456889 - 104.3421)/(1 + (G24/39.91202)^3.274503))/C15 -> 10.46669 | I24: =G21/C16 -> 2 | J24: =(I24/20)*100 -> 10 | K24: =(0.3*F24)+(0.3*H24)+(0.4*J24) -> 10.140007
F25: Score Impact Direct | G25: Total point 10 round | H25: Score Impact sur 10 rounds | I25: Moy / Mana | J25: Score efficacité | K25: Final Score Quick
F26: =(I21/(20*C15))*100 -> 5 | G26: =G18*I21 -> 5 | H26: =(104.3421 + (9.456889 - 104.3421)/(1 + (G26/39.91202)^3.274503))/C15 -> 9.5622492 | I26: =I21/C16 -> 1 | J26: =(I26/20)*100 -> 5 | K26: =(0.3*F26)+(0.3*H26)+(0.4*J26) -> 6.3686748
F27: Score Init | G27: =(C17/5)*100 -> 20
F28: Total score | G28: =(0.25*K26)+(0.6*K24)+(0.15*G27) -> 10.676173
A30: =References!$F$2 -> Name | C30: Super Attack
A31: =References!$F$3 -> Class | C31: =References!$E$2 -> Creature | I31: =_xlfn.FLOOR.MATH(10/IF(OR(C34=1,C34=0),2,C34)) -> 5
A32: =References!$F$4 -> Type | C32: =References!$B$2 -> Offensive
A33: =References!$F$5 -> Nb. Targets | C33: 1
A34: =References!$F$6 -> Energy cost | C34: 2
A35: Initiative | C35: 1
A36: Critical Chance | C36: 0 | F36: Number times on 10 rounds | G36: =_xlfn.FLOOR.MATH(10/IF(OR(C34=1,C34=0),2,C34)) -> 5
A37: =References!$G$2 -> Type | B37: =References!$G$3 -> Stat | C37: =References!$G$7 -> Nb | D37: =References!$G$8 -> Turns | F37: Nb with crit chance | G37: NbCrit with turns | H37: Nb quick | I37: NbQuick with turns
A38: =References!$C$2 -> Direct | B38: =References!$A$2 -> dmg | C38: 3 | F38: =(C38+(1*C36))*C33 -> 3 | G38: =IF(D38="",F38,F38*D38) -> 3 | H38: =(C38-(1-C36)*1)*C33 -> 2 | I38: =IF(D38="",H38,H38*D38) -> 2 | R38: =C38-(1-C36)*1 -> 2
F39: Total dmg | G39: =SUM(G38) -> 3 | I39: =SUM(I38) -> 2
F41: Score Impact Direct | G41: Total point 10 round | H41: Score Impact sur 10 rounds | I41: Moy / Mana | J41: Score efficacité | K41: Final Score Standard
F42: =(G39/(20*C33))*100 -> 15 | G42: =G39*G36 -> 15 | H42: =(104.3421 + (9.456889 - 104.3421)/(1 + (G42/39.91202)^3.274503))/C33 -> 13.157038 | I42: =G39/C34 -> 1.5 | J42: =(I42/20)*100 -> 7.5 | K42: =(0.3*F42)+(0.3*H42)+(0.4*J42) -> 11.447111
F43: Score Impact Direct | G43: Total point 10 round | H43: Score Impact sur 10 rounds | I43: Moy / Mana | J43: Score efficacité | K43: Final Score Quick
F44: =(I39/(20*C33))*100 -> 10 | G44: =G36*I39 -> 10 | H44: =(104.3421 + (9.456889 - 104.3421)/(1 + (G44/39.91202)^3.274503))/C33 -> 10.46669 | I44: =I39/C34 -> 1 | J44: =(I44/20)*100 -> 5 | K44: =(0.3*F44)+(0.3*H44)+(0.4*J44) -> 8.1400071
F45: Score Init | G45: =(C35/5)*100 -> 20
F46: Total score | G46: =(0.25*K44)+(0.6*K42)+(0.15*G45) -> 11.903269
...

Sheet Scores
A1: =References!$C$2 -> Direct | B1: 2
A2: =References!$C$3 -> Temp | B2: 1
A3: =References!$C$4 -> SelfDirect | B3: 2
A4: =References!$C$5 -> SelfTemp | B4: 1
A5: dmg | B5: 1

Sheet References
A2: dmg | B2: Offensive | C2: Direct | D2: Brawler | E2: Creature | F2: Name | G2: Type | H2: High initiative
A3: hp | B3: Defensive | C3: Temp | D3: Scoundrel | E3: Mercenary | F3: Class | G3: Stat | H3: Standard
A4: enrg | B4: Passive | C4: SelfDirect | D4: Sorcerer | E4: Warlord | F4: Type | G4: Nb | H4: Low initiative
A5: def | C5: SelfTemp | E5: Berserker | F5: Nb. Targets | G5: Turns
A6: spd | E6: Trickster | F6: Energy cost | G6: %
A7: rtl | E7: Assassin | G7: Nb
A8: stun | E8: Necromancer | G8: Turns
A9: roll | E9: Wizard | G9: Nb
E10: Leech | G10: Turns
E11: Shaman | G11: %
E12: Leech

Sheet Fighter
A1: FIGHTER
E3: =References!$F$2 -> Name | G3: Attaque cool | R3: =References!$F$2 -> Name | T3: Shield
E4: =References!$F$3 -> Class | G4: =References!$D$2 -> Brawler | R4: =References!$F$3 -> Class | T4: =References!$D$2 -> Brawler
E5: =References!$F$4 -> Type | G5: =References!$B$2 -> Offensive | R5: =References!$F$4 -> Type | T5: =References!$B$3 -> Defensive
E6: =References!$F$5 -> Nb. Targets | G6: 1 | R6: =References!$F$5 -> Nb. Targets | T6: 1
E7: =References!$F$6 -> Energy cost | G7: 1 | R7: =References!$F$6 -> Energy cost | T7: 2
A9: =References!$G$2 -> Type | B9: =References!$G$3 -> Stat | C9: =References!$G$4 -> Nb | D9: =References!$G$5 -> Turns | E9: =References!$G$6 -> % | F9: =References!$G$7 -> Nb | G9: =References!$G$8 -> Turns | H9: =References!$G$9 -> Nb | I9: =References!$G$10 -> Turns | J9: =References!$G$11 -> % | N9: =References!$G$2 -> Type | O9: =References!$G$3 -> Stat | P9: =References!$G$4 -> Nb | Q9: =References!$G$5 -> Turns | R9: =References!$G$6 -> % | S9: =References!$G$7 -> Nb | T9: =References!$G$8 -> Turns | U9: =References!$G$9 -> Nb | V9: =References!$G$10 -> Turns | W9: =References!$G$11 -> %
C10: =References!$H$2 -> High initiative | F10: =References!$H$3 -> Standard | H10: =References!$H$4 -> Low initiative | P10: =References!$H$2 -> High initiative | S10: =References!$H$3 -> Standard | U10: =References!$H$4 -> Low initiative
A11: =References!$C$2 -> Direct | B11: =References!$A$2 -> dmg | C11: 1 | E11: 100 | F11: 2 | H11: 2 | J11: 100 | N11: =References!$C$2 -> Direct | O11: =References!$A$5 -> def | P11: 1 | R11: 100 | S11: 1 | U11: 1 | W11: 100
N12: =References!$C$3 -> Temp | O12: =References!$A$5 -> def | P12: 1 | Q12: 1 | R12: 100 | S12: 1 | T12: 2 | U12: 1 | V12: 3 | W12: 100
E19: =References!$F$2 -> Name | G19: Balance | R19: =References!$F$2 -> Name | T19: Full Plate | AE19: =References!$F$2 -> Name | AG19: Double Hit
E20: =References!$F$3 -> Class | G20: =References!$E$3 -> Mercenary | R20: =References!$F$3 -> Class | T20: =References!$E$4 -> Warlord | AE20: =References!$F$3 -> Class | AG20: =References!$E$5 -> Berserker
E21: =References!$F$4 -> Type | G21: =References!$B$2 -> Offensive | R21: =References!$F$4 -> Type | T21: =References!$B$4 -> Passive | AE21: =References!$F$4 -> Type | AG21: =References!$B$2 -> Offensive
E22: =References!$F$5 -> Nb. Targets | G22: 1 | R22: =References!$F$5 -> Nb. Targets | AE22: =References!$F$5 -> Nb. Targets | AG22: 1
E23: =References!$F$6 -> Energy cost | G23: 3 | R23: =References!$F$6 -> Energy cost | AE23: =References!$F$6 -> Energy cost | AG23: 3
A25: =References!$G$2 -> Type | B25: =References!$G$3 -> Stat | C25: =References!$G$4 -> Nb | D25: =References!$G$5 -> Turns | E25: =References!$G$6 -> % | F25: =References!$G$7 -> Nb | G25: =References!$G$8 -> Turns | H25: =References!$G$9 -> Nb | I25: =References!$G$10 -> Turns | J25: =References!$G$11 -> % | N25: =References!$G$2 -> Type | O25: =References!$G$3 -> Stat | P25: =References!$G$4 -> Nb | Q25: =References!$G$5 -> Turns | R25: =References!$G$6 -> % | S25: =References!$G$7 -> Nb | T25: =References!$G$8 -> Turns | U25: =References!$G$9 -> Nb | V25: =References!$G$10 -> Turns | W25: =References!$G$11 -> % | AA25: =References!$G$2 -> Type | AB25: =References!$G$3 -> Stat | AC25: =References!$G$4 -> Nb | AD25: =References!$G$5 -> Turns | AE25: =References!$G$6 -> % | AF25: =References!$G$7 -> Nb | AG25: =References!$G$8 -> Turns | AH25: =References!$G$9 -> Nb | AI25: =References!$G$10 -> Turns | AJ25: =References!$G$11 -> %
C26: =References!$H$2 -> High initiative | F26: =References!$H$3 -> Standard | H26: =References!$H$4 -> Low initiative | P26: =References!$H$2 -> High initiative | S26: =References!$H$3 -> Standard | U26: =References!$H$4 -> Low initiative | AC26: =References!$H$2 -> High initiative | AF26: =References!$H$3 -> Standard | AH26: =References!$H$4 -> Low initiative
A27: =References!$C$2 -> Direct | B27: =References!$A$2 -> dmg | C27: 3 | E27: 100 | F27: 4 | H27: 5 | J27: 100 | N27: =References!$B$4 -> Passive | O27: =References!$A$5 -> def | S27: 1 | AA27: =References!$C$2 -> Direct | AB27: =References!$A$2 -> dmg | AC27: 3 | AE27: 100 | AF27: 3 | AH27: 4 | AJ27: 100
A28: =References!$C$4 -> SelfDirect | B28: =References!$A$5 -> def | C28: 1 | E28: 100 | F28: 1 | H28: 1 | J28: 100 | AA28: =References!$C$2 -> Direct | AB28: =References!$A$2 -> dmg | AC28: 2 | AE28: 100 | AF28: 3 | AH28: 3 | AJ28: 100
A29: =References!$C$5 -> SelfTemp | B29: =References!$A$5 -> def | C29: 1 | D29: 1 | E29: 100 | F29: 1 | G29: 1 | H29: 1 | I29: 2 | J29: 100
E35: =References!$F$2 -> Name | G35: Cleave | R35: =References!$F$2 -> Name | T35: Attack Stun | AE35: =References!$F$2 -> Name | AG35: Tornado
E36: =References!$F$3 -> Class | G36: =References!$E$3 -> Mercenary | R36: =References!$F$3 -> Class | T36: =References!$E$4 -> Warlord | AE36: =References!$F$3 -> Class | AG36: =References!$E$5 -> Berserker
E37: =References!$F$4 -> Type | G37: =References!$B$2 -> Offensive | R37: =References!$F$4 -> Type | T37: =References!$B$2 -> Offensive | AE37: =References!$F$4 -> Type | AG37: =References!$B$3 -> Defensive
E38: =References!$F$5 -> Nb. Targets | G38: 2 | R38: =References!$F$5 -> Nb. Targets | T38: 1 | AE38: =References!$F$5 -> Nb. Targets | AG38: 3
E39: =References!$F$6 -> Energy cost | G39: 4 | R39: =References!$F$6 -> Energy cost | T39: 3 | AE39: =References!$F$6 -> Energy cost | AG39: 2
